<?xml version='1.0' encoding='UTF-8'?>
<!-- =================================================================================== -->
<!-- |    This document was autogenerated by xacro from drawer_one_sided_handle.xacro  | -->
<!-- |    EDITING THIS FILE BY HAND IS NOT RECOMMENDED                                 | -->
<!-- =================================================================================== -->
<robot xmlns:xacro="http://ros.org/wiki/xacro" name="drawer">
  <!-- Scaled non-uniformly with factors x=0.3, y=0.6, z=0.5; box sizes, origins, prismatic travel, masses, and inertias updated. --><material name="omni/Blue">
    <color rgba="0 0 0.8 1"/>
  </material>
  <material name="omni/Red">
    <color rgba="1 0 0 1"/>
  </material>
  <material name="omni/White">
    <color rgba="1 1 1 1"/>
  </material>
  <material name="omni/Green">
    <color rgba="0 1 0 1"/>
  </material>
  <material name="omni/Yellow">
    <color rgba="1 1 0 1"/>
  </material>
  <material name="omni/LightGrey">
    <color rgba="0.6 0.6 0.6 1"/>
  </material>
  <material name="omni/DarkGrey">
    <color rgba="0.4 0.4 0.4 1"/>
  </material>
  <link name="base_link">    
    </link>
  <link name="drawer">
    <!-- Bottom wall -->
    <visual>
      <origin rpy="0 0 0" xyz="0 0 -0.065"/>
      <geometry>
        <box size="0.3 0.36 0.025"/> 
      </geometry>
      <material name="omni/LightGrey"/>
    </visual>
    <collision>
      <origin rpy="0 0 0" xyz="0 0 -0.065"/>
      <geometry>
        <box size="0.3 0.36 0.025"/>
      </geometry>
    </collision>
    <!-- Right wall -->
    <visual>
      <origin rpy="0 0 0" xyz="0 0.165 0.01125"/>
      <geometry>
        <box size="0.3 0.03 0.1275"/>
      </geometry>
      <material name="omni/LightGrey"/>
    </visual>
    <collision>
      <origin rpy="0 0 0" xyz="0 0.165 0.01125"/>
      <geometry>
        <box size="0.3 0.03 0.1275"/>
      </geometry>
    </collision>
    <!-- Left wall -->
    <visual>
      <origin rpy="0 0 0" xyz="0 -0.165 0.01125"/>
      <geometry>
        <box size="0.3 0.03 0.1275"/>
      </geometry>
      <material name="omni/LightGrey"/>
    </visual>
    <collision>
      <origin rpy="0 0 0" xyz="0 -0.165 0.01125"/>
      <geometry>
        <box size="0.3 0.03 0.1275"/>
      </geometry>
    </collision>
    <!-- Back wall -->
    <visual>
      <origin rpy="0 0 0" xyz="-0.1425 0 0.01125"/>
      <geometry>
        <box size="0.015 0.3 0.1275"/> 
      </geometry>
      <material name="omni/LightGrey"/>
    </visual>
    <collision>
      <origin rpy="0 0 0" xyz="-0.1425 0 0.01125"/>
      <geometry>
        <box size="0.015 0.3 0.1275"/> 
      </geometry>
    </collision>
    <!-- Front wall -->
    <visual>
      <origin rpy="0 0 0" xyz="0.1425 0 0.01125"/>
      <geometry>
        <box size="0.015 0.3 0.1275"/> 
      </geometry>
      <material name="omni/LightGrey"/>
    </visual>
    <collision>
      <origin rpy="0 0 0" xyz="0.1425 0 0.01125"/>
      <geometry>
        <box size="0.015 0.3 0.1275"/> 
      </geometry>
    </collision>
    <inertial>
      <origin rpy="0 0 0" xyz="0 0 0"/>
      <mass value="0.4500"/>
      <inertia ixx="0.0085763427" ixy="0.0000000000" ixz="0.0000000000" iyy="0.0056727301" iyz="0.0000000000" izz="0.0118099038"/>
    </inertial>
  </link>
  <joint name="base_drawer_joint" type="prismatic">
    <origin rpy="0 0 0" xyz="0 0 0"/>
    <parent link="base_link"/>
    <child link="drawer"/>
    <dynamics damping="1.0" friction="1.0"/>
    <limit effort="0.1" lower="0" upper="0.3" velocity="10.0"/>
    <axis xyz="1 0 0"/>
  </joint>
  <link name="left_wall">
    <visual>
      <origin rpy="0 0 0" xyz="0 0 0"/>
      <geometry>
        <box size="0.303 0.012 0.16"/>
      </geometry>
      <material name="omni/White"/>
    </visual>
    <collision>
      <origin rpy="0 0 0" xyz="0 0 0"/>
      <geometry>
        <box size="0.303 0.012 0.16"/>
      </geometry>
    </collision>
    <inertial>
      <!-- CENTER OF MASS -->
      <origin rpy="0 0 0" xyz="0 0 0"/>
      <mass value="0.2250"/>
      <!-- box inertia: 1/12*m(y^2+z^2), ... -->
      <inertia ixx="0.0004827000" ixy="0.0000000000" ixz="0.0000000000" iyy="0.0022014187" iyz="0.0000000000" izz="0.0017241188"/>
    </inertial>
  </link>
  <joint name="b_2_lw" type="fixed">
    <origin rpy="0 0 0" xyz="-0.003 -0.192 0"/>
    <parent link="base_link"/>
    <child link="left_wall"/>
  </joint>
  <link name="right_wall">
    <visual>
      <origin rpy="0 0 0" xyz="0 0 0"/>
      <geometry>
        <box size="0.303 0.012 0.16"/>
      </geometry>
      <material name="omni/White"/>
    </visual>
    <collision>
      <origin rpy="0 0 0" xyz="0 0 0"/>
      <geometry>
        <box size="0.303 0.012 0.16"/>
      </geometry>
    </collision>
    <inertial>
      <!-- CENTER OF MASS -->
      <origin rpy="0 0 0" xyz="0 0 0"/>
      <mass value="0.2250"/>
      <!-- box inertia: 1/12*m(y^2+z^2), ... -->
      <inertia ixx="0.0004827000" ixy="0.0000000000" ixz="0.0000000000" iyy="0.0022014187" iyz="0.0000000000" izz="0.0017241188"/>
    </inertial>
  </link>
  <joint name="b_2_rw" type="fixed">
    <origin rpy="0 0 0" xyz="-0.003 0.192 0"/>
    <parent link="base_link"/>
    <child link="right_wall"/>
  </joint>
  <link name="bottom_wall">
    <visual>
      <origin rpy="0 0 0" xyz="0 0 0"/>
      <geometry>
        <box size="0.303 0.396 0.01"/>
      </geometry>
      <material name="omni/White"/>
    </visual>
    <collision>
      <origin rpy="0 0 0" xyz="0 0 0"/>
      <geometry>
        <box size="0.303 0.396 0.01"/>
      </geometry>
    </collision>
    <inertial>
      <!-- CENTER OF MASS -->
      <origin rpy="0 0 0" xyz="0 0 0"/>
      <mass value="0.2250"/>
      <!-- box inertia: 1/12*m(y^2+z^2), ... -->
      <inertia ixx="0.0029421750" ixy="0.0000000000" ixz="0.0000000000" iyy="0.0017232938" iyz="0.0000000000" izz="0.0046617188"/>
    </inertial>
  </link>
  <joint name="b_2_bw" type="fixed">
    <origin rpy="0 0 0" xyz="-0.003 0 -0.085"/>
    <parent link="base_link"/>
    <child link="bottom_wall"/>
  </joint>
  <link name="top_wall">
    <visual>
      <origin rpy="0 0 0" xyz="0 0 0"/>
      <geometry>
        <box size="0.303 0.396 0.01"/>
      </geometry>
      <material name="omni/White"/>
    </visual>
    <collision>
      <origin rpy="0 0 0" xyz="0 0 0"/>
      <geometry>
        <box size="0.303 0.396 0.01"/>
      </geometry>
    </collision>
    <inertial>
      <!-- CENTER OF MASS -->
      <origin rpy="0 0 0" xyz="0 0 0"/>
      <mass value="0.2250"/>
      <!-- box inertia: 1/12*m(y^2+z^2), ... -->
      <inertia ixx="0.0029421750" ixy="0.0000000000" ixz="0.0000000000" iyy="0.0017232938" iyz="0.0000000000" izz="0.0046617188"/>
    </inertial>
  </link>
  <joint name="b_2_tw" type="fixed">
    <origin rpy="0 0 0" xyz="-0.003 0 0.085"/>
    <parent link="base_link"/>
    <child link="top_wall"/>
  </joint>
  <link name="back_wall">
    <visual>
      <origin rpy="0 0 0" xyz="0 0 0"/>
      <geometry>
        <box size="0.006 0.396 0.18"/>
      </geometry>
      <material name="omni/White"/>
    </visual>
    <collision>
      <origin rpy="0 0 0" xyz="0 0 0"/>
      <geometry>
        <box size="0.006 0.396 0.18"/>
      </geometry>
    </collision>
    <inertial>
      <!-- CENTER OF MASS -->
      <origin rpy="0 0 0" xyz="0 0 0"/>
      <mass value="0.2250"/>
      <!-- box inertia: 1/12*m(y^2+z^2), ... -->
      <inertia ixx="0.0035478000" ixy="0.0000000000" ixz="0.0000000000" iyy="0.0006081750" iyz="0.0000000000" izz="0.0029409750"/>
    </inertial>
  </link>
  <joint name="b_2_backw" type="fixed">
    <origin rpy="0 0 0" xyz="-0.156 0 0"/>
    <parent link="base_link"/>
    <child link="back_wall"/>
  </joint>
  

</robot>
